Workbook

Sheet Pre-season info
A1: Team | B1: Driver | D1: Reserve Drivers | E1: Team Principal | F1: Engine | H1: Mid-Season Driver Changes
A2: Mclaren | B2: Lando Norris | C2: 🇬🇧4 | E2: Andrea Stella | F2: Mercedes
B3: Oscar Piastri | C3: 🇦🇺81
A4: Mercedes | B4: George Russell | C4: 🇬🇧63 | E4: Toto Wolff | F4: Mercedes
B5: Kimi Antonelli | C5: 🇮🇹12
A6: Red Bull Racing | B6: Max Verstappen | C6: 🇳🇱33 | E6: Laurent Mekies | F6: Red Bull Ford
A8: Ferrari | B8: Lewis Hamilton | C8: 🇬🇧44 | E8: Fred Vasseur | F8: Ferrari
B9: Charles Leclerc | C9: 🇲🇨16
A10: Williams | B10: Carlos Sainz | C10: 🇪🇸55 | E10: James Vowles | F10: Mercedes
B11: Alex Albon | C11: 🇹🇭23
A12: Racing Bulls | E12: Alan Permane | F12: Red Bull Ford
A14: Haas | B14: Ollie Bearman | C14: 🇬🇧87 | E14: Ayao Komatsu | F14: Ferrari
B15: Esteban Ocon | C15: 🇫🇷31
A16: Aston Martin | B16: Fernando Alonso | C16: 🇪🇸14 | E16: Adrian Newey | F16: Honda
B17: Lance Stroll | C17: 🇨🇦18
A18: Audi | B18: Nico Hulkenberg | C18: 🇩🇪27 | E18: Jonathan Wheatley | F18: Audi
B19: Gabriel Bortoleto | C19: 🇧🇷5
A20: Alpine | B20: Pierre Gasly | C20: 🇫🇷10 | E20: Flavio Briatore | F20: Mercedes
B21: Franco Colapinto | C21: 🇦🇷43
A22: Cadillac | B22: Valterri Bottas | C22: 🇫🇮77 | D22: Colton Herta | E22: Graeme Lowdon | F22: Ferrari
B23: Sergio Perez | C23: 🇲🇽11

Sheet Predictions
A1: WDC Predictions | D1: WCC Predictions
A2: Position | B2: Driver | D2: Position | E2: Team
A3: 1 | D3: 1
A4: 2 | D4: 2
A5: 3 | D5: 3
A6: 4 | D6: 4
A7: 5 | D7: 5
A8: 6 | D8: 6
A9: 7 | D9: 7
A10: 8 | D10: 8
A11: 9 | D11: 9
A12: 10 | D12: 10
A13: 11 | D13: 11
A14: 12
A15: 13
A16: 14
A17: 15
A18: 16
A19: 17
A20: 18
A21: 19
A22: 20
A23: 21
A24: 22

Sheet Final WDC
A1: Position | B1: Driver | C1: Points
A2: 1
A3: 2
A4: 3
A5: 4
A6: 5
A7: 6
A8: 7
A9: 8
A10: 9
A11: 10
A12: 11
A13: 12
... A23: 22

Sheet Final WCC
A1: Position | B1: Team | C1: Points
A2: 1
A3: 2
A4: 3
A5: 4
A6: 5
A7: 6
A8: 7
A9: 8
A10: 9
A11: 10
A12: 11

Sheet Live WDC
A1: Position | B1: Driver | C1: Points
A2: 1 | B2: {=SORT(Table9[], 2, FALSE)} -> Norris | C2: 0
A3: 2 | B3: Piastri | C3: 0
A4: 3 | B4: Russell | C4: 0
A5: 4 | B5: Antonelli | C5: 0
A6: 5 | B6: Verstappen | C6: 0
A7: 6 | B7: UNKNOWN 1 | C7: 0
A8: 7 | B8: Leclerc | C8: 0
A9: 8 | B9: Hamilton | C9: 0
A10: 9 | B10: Sainz | C10: 0
A11: 10 | B11: Albon | C11: 0
A12: 11 | B12: UNKNOWN 2 | C12: 0
A13: 12 | B13: UNKNOWN 3 | C13: 0
A14: 13 | B14: Bearman | C14: 0
... A23: 22 | B23: Perez | C23: 0

Sheet Live WCC
A1: Position | B1: Team | C1: Points
A2: 1 | B2: {=SORT(Table10[], 2, FALSE)} -> Mclaren | C2: 0
A3: 2 | B3: Mercedes | C3: 0
A4: 3 | B4: Red Bull Racing | C4: 0
A5: 4 | B5: Ferrari | C5: 0
A6: 5 | B6: Williams | C6: 0
A7: 6 | B7: Racing Bulls | C7: 0
A8: 7 | B8: Haas | C8: 0
A9: 8 | B9: Aston Martin | C9: 0
A10: 9 | B10: Audi | C10: 0
A11: 10 | B11: Alpine | C11: 0
A12: 11 | B12: Cadillac | C12: 0

Sheet Teammate Stats
A1: Team | B1: Driver 1 | C1: Points 1 | D1: Driver 2 | E1: Points 2 | F1: Points Difference
A2: Mclaren | B2: Lando Norris | C2: ='Live Points Per Race'!B26 -> 0 | D2: Oscar Piastri | E2: ='Live Points Per Race'!C26 -> 0 | F2: =ABS(C2-E2) -> 0
A3: Mercedes | B3: George Russell | C3: ='Live Points Per Race'!D26 -> 0 | D3: Kimi Antonelli | E3: ='Live Points Per Race'!E26 -> 0 | F3: =ABS(C3-E3) -> 0
A4: Red Bull Racing | B4: Max Verstappen | C4: ='Live Points Per Race'!F26 -> 0 | D4: UNKNOWN 1 | E4: ='Live Points Per Race'!G26 -> 0 | F4: =ABS(C4-E4) -> 0
A5: Ferrari | B5: Charles Leclerc | C5: ='Live Points Per Race'!H26 -> 0 | D5: Lewis Hamilton | E5: ='Live Points Per Race'!I26 -> 0 | F5: =ABS(C5-E5) -> 0
A6: Williams | B6: Carlos Sainz | C6: ='Live Points Per Race'!J26 -> 0 | D6: Alex Albon | E6: ='Live Points Per Race'!K26 -> 0 | F6: =ABS(C6-E6) -> 0
A7: Racing Bulls | B7: UNKNOWN 2 | C7: ='Live Points Per Race'!L26 -> 0 | D7: UNKNOWN 3 | E7: ='Live Points Per Race'!M26 -> 0 | F7: =ABS(C7-E7) -> 0
A8: Haas | B8: Ollie Bearman | C8: ='Live Points Per Race'!N26 -> 0 | D8: Esteban Ocon | E8: ='Live Points Per Race'!O26 -> 0 | F8: =ABS(C8-E8) -> 0
A9: Aston Martin | B9: Fernando Alonso | C9: ='Live Points Per Race'!P26 -> 0 | D9: Lance Stroll | E9: ='Live Points Per Race'!Q26 -> 0 | F9: =ABS(C9-E9) -> 0
A10: Audi | B10: Nico Hulkenberg | C10: ='Live Points Per Race'!R26 -> 0 | D10: Gabriel Bortoleto | E10: ='Live Points Per Race'!S26 -> 0 | F10: =ABS(C10-E10) -> 0
A11: Alpine | B11: Pierre Gasly | C11: ='Live Points Per Race'!T26 -> 0 | D11: Franco Colapinto | E11: ='Live Points Per Race'!U26 -> 0 | F11: =ABS(C11-E11) -> 0
A12: Cadillac | B12: Valterri Bottas | C12: ='Live Points Per Race'!V26 -> 0 | D12: Sergio Perez | E12: ='Live Points Per Race'!W26 -> 0 | F12: =ABS(C12-E12) -> 0

Sheet Live Points Per Race
A1: Points | B1: Norris | C1: Piastri | D1: Russell | E1: Antonelli | F1: Verstappen | G1: UNKNOWN 1 | H1: Leclerc | I1: Hamilton | J1: Sainz | K1: Albon | L1: UNKNOWN 2 | M1: UNKNOWN 3 | N1: Bearman | O1: Ocon | P1: Alonso | Q1: Stroll | R1: Hulkenberg | S1: Bortoleto | T1: Gasly | U1: Colapinto | V1: Bottas | W1: Perez | Y1: Driver | Z1: Points | AB1: Team | AC1: Points
A2: Australia | B2: =Australia!X2 | C2: =Australia!X3 | D2: =Australia!X4 | E2: =Australia!X5 | F2: =Australia!X6 | G2: =Australia!X7 | H2: =Australia!X8 | I2: =Australia!X9 | J2: =Australia!X10 | K2: =Australia!X11 | L2: =Australia!X12 | M2: =Australia!X13 | N2: =Australia!X14 | O2: =Australia!X15 | P2: =Australia!X16 | Q2: =Australia!X17 | R2: =Australia!X18 | S2: =Australia!X19 | T2: =Australia!X20 | U2: =Australia!X21 | V2: =Australia!X22 | W2: =Australia!X23 | Y2: Norris | Z2: =B26 -> 0 | AB2: Mclaren | AC2: =Z2+Z3 -> 0
A3: China | B3: =China!X2 | C3: =China!X3 | D3: =China!X4 | E3: =China!X5 | F3: =China!X6 | G3: =China!X7 | H3: =China!X8 | I3: =China!X9 | J3: =China!X10 | K3: =China!X11 | L3: =China!X12 | M3: =China!X13 | N3: =China!X14 | O3: =China!X15 | P3: =China!X16 | Q3: =China!X17 | R3: =China!X18 | S3: =China!X19 | T3: =China!X20 | U3: =China!X21 | V3: =China!X22 | W3: =China!X23 | Y3: Piastri | Z3: =C26 -> 0 | AB3: Mercedes | AC3: =Z4+Z5 -> 0
A4: Japan | B4: =Japan!X2 | C4: =Japan!X3 | D4: =Japan!X4 | E4: =Japan!X5 | F4: =Japan!X6 | G4: =Japan!X7 | H4: =Japan!X8 | I4: =Japan!X9 | J4: =Japan!X10 | K4: =Japan!X11 | L4: =Japan!X12 | M4: =Japan!X13 | N4: =Japan!X14 | O4: =Japan!X15 | P4: =Japan!X16 | Q4: =Japan!X17 | R4: =Japan!X18 | S4: =Japan!X19 | T4: =Japan!X20 | U4: =Japan!X21 | V4: =Japan!X22 | W4: =Japan!X23 | Y4: Russell | Z4: =D26 -> 0 | AB4: Red Bull Racing | AC4: =Z6+Z7 -> 0
A5: Bahrain | B5: =Bahrain!X2 | C5: =Bahrain!X3 | D5: =Bahrain!X4 | E5: =Bahrain!X5 | F5: =Bahrain!X6 | G5: =Bahrain!X7 | H5: =Bahrain!X8 | I5: =Bahrain!X9 | J5: =Bahrain!X10 | K5: =Bahrain!X11 | L5: =Bahrain!X12 | M5: =Bahrain!X13 | N5: =Bahrain!X14 | O5: =Bahrain!X15 | P5: =Bahrain!X16 | Q5: =Bahrain!X17 | R5: =Bahrain!X18 | S5: =Bahrain!X19 | T5: =Bahrain!X20 | U5: =Bahrain!X21 | V5: =Bahrain!X22 | W5: =Bahrain!X23 | Y5: Antonelli | Z5: =E26 -> 0 | AB5: Ferrari | AC5: =Z8+Z9 -> 0
A6: Saudi Arabia | B6: ='Saudi Arabia'!X2 | C6: ='Saudi Arabia'!X3 | D6: ='Saudi Arabia'!X4 | E6: ='Saudi Arabia'!X5 | F6: ='Saudi Arabia'!X6 | G6: ='Saudi Arabia'!X7 | H6: ='Saudi Arabia'!X8 | I6: ='Saudi Arabia'!X9 | J6: ='Saudi Arabia'!X10 | K6: ='Saudi Arabia'!X11 | L6: ='Saudi Arabia'!X12 | M6: ='Saudi Arabia'!X13 | N6: ='Saudi Arabia'!X14 | O6: ='Saudi Arabia'!X15 | P6: ='Saudi Arabia'!X16 | Q6: ='Saudi Arabia'!X17 | R6: ='Saudi Arabia'!X18 | S6: ='Saudi Arabia'!X19 | T6: ='Saudi Arabia'!X20 | U6: ='Saudi Arabia'!X21 | V6: ='Saudi Arabia'!X22 | W6: ='Saudi Arabia'!X23 | Y6: Verstappen | Z6: =F26 -> 0 | AB6: Williams | AC6: =Z10+Z11 -> 0
A7: Miami | B7: =Miami!X2 | C7: =Miami!X3 | D7: =Miami!X4 | E7: =Miami!X5 | F7: =Miami!X6 | G7: =Miami!X7 | H7: =Miami!X8 | I7: =Miami!X9 | J7: =Miami!X10 | K7: =Miami!X11 | L7: =Miami!X12 | M7: =Miami!X13 | N7: =Miami!X14 | O7: =Miami!X15 | P7: =Miami!X16 | Q7: =Miami!X17 | R7: =Miami!X18 | S7: =Miami!X19 | T7: =Miami!X20 | U7: =Miami!X21 | V7: =Miami!X22 | W7: =Miami!X23 | Y7: UNKNOWN 1 | Z7: =G26 -> 0 | AB7: Racing Bulls | AC7: =Z12+Z13 -> 0
A8: Canada | B8: =Canada!X2 | C8: =Canada!X3 | D8: =Canada!X4 | E8: =Canada!X5 | F8: =Canada!X6 | G8: =Canada!X7 | H8: =Canada!X8 | I8: =Canada!X9 | J8: =Canada!X10 | K8: =Canada!X11 | L8: =Canada!X12 | M8: =Canada!X13 | N8: =Canada!X14 | O8: =Canada!X15 | P8: =Canada!X16 | Q8: =Canada!X17 | R8: =Canada!X18 | S8: =Canada!X19 | T8: =Canada!X20 | U8: =Canada!X21 | V8: =Canada!X22 | W8: =Canada!X23 | Y8: Leclerc | Z8: =H26 -> 0 | AB8: Haas | AC8: =Z14+Z15 -> 0
A9: Monaco | B9: =Monaco!X2 | C9: =Monaco!X3 | D9: =Monaco!X4 | E9: =Monaco!X5 | F9: =Monaco!X6 | G9: =Monaco!X7 | H9: =Monaco!X8 | I9: =Monaco!X9 | J9: =Monaco!X10 | K9: =Monaco!X11 | L9: =Monaco!X12 | M9: =Monaco!X13 | N9: =Monaco!X14 | O9: =Monaco!X15 | P9: =Monaco!X16 | Q9: =Monaco!X17 | R9: =Monaco!X18 | S9: =Monaco!X19 | T9: =Monaco!X20 | U9: =Monaco!X21 | V9: =Monaco!X22 | W9: =Monaco!X23 | Y9: Hamilton | Z9: =I26 -> 0 | AB9: Aston Martin | AC9: =Z16+Z17 -> 0
A10: Barcelona | B10: =Barcelona!X2 | C10: =Barcelona!X3 | D10: =Barcelona!X4 | E10: =Barcelona!X5 | F10: =Barcelona!X6 | G10: =Barcelona!X7 | H10: =Barcelona!X8 | I10: =Barcelona!X9 | J10: =Barcelona!X10 | K10: =Barcelona!X11 | L10: =Barcelona!X12 | M10: =Barcelona!X13 | N10: =Barcelona!X14 | O10: =Barcelona!X15 | P10: =Barcelona!X16 | Q10: =Barcelona!X17 | R10: =Barcelona!X18 | S10: =Barcelona!X19 | T10: =Barcelona!X20 | U10: =Barcelona!X21 | V10: =Barcelona!X22 | W10: =Barcelona!X23 | Y10: Sainz | Z10: =J26 -> 0 | AB10: Audi | AC10: =Z18+Z19 -> 0
A11: Austria | B11: =Austria!X2 | C11: =Austria!X3 | D11: =Austria!X4 | E11: =Austria!X5 | F11: =Austria!X6 | G11: =Austria!X7 | H11: =Austria!X8 | I11: =Austria!X9 | J11: =Austria!X10 | K11: =Austria!X11 | L11: =Austria!X12 | M11: =Austria!X13 | N11: =Austria!X14 | O11: =Austria!X15 | P11: =Austria!X16 | Q11: =Austria!X17 | R11: =Austria!X18 | S11: =Austria!X19 | T11: =Austria!X20 | U11: =Austria!X21 | V11: =Austria!X22 | W11: =Austria!X23 | Y11: Albon | Z11: =K26 -> 0 | AB11: Alpine | AC11: =Z20+Z21 -> 0
A12: Great Britain | B12: ='Great Britain'!X2 | C12: ='Great Britain'!X3 | D12: ='Great Britain'!X4 | E12: ='Great Britain'!X5 | F12: ='Great Britain'!X6 | G12: ='Great Britain'!X7 | H12: ='Great Britain'!X8 | I12: ='Great Britain'!X9 | J12: ='Great Britain'!X10 | K12: ='Great Britain'!X11 | L12: ='Great Britain'!X12 | M12: ='Great Britain'!X13 | N12: ='Great Britain'!X14 | O12: ='Great Britain'!X15 | P12: ='Great Britain'!X16 | Q12: ='Great Britain'!X17 | R12: ='Great Britain'!X18 | S12: ='Great Britain'!X19 | T12: ='Great Britain'!X20 | U12: ='Great Britain'!X21 | V12: ='Great Britain'!X22 | W12: ='Great Britain'!X23 | Y12: UNKNOWN 2 | Z12: =L26 -> 0 | AB12: Cadillac | AC12: =Z22+Z23 -> 0
A13: Belgium | B13: =Belgium!X2 | C13: =Belgium!X3 | D13: =Belgium!X4 | E13: =Belgium!X5 | F13: =Belgium!X6 | G13: =Belgium!X7 | H13: =Belgium!X8 | I13: =Belgium!X9 | J13: =Belgium!X10 | K13: =Belgium!X11 | L13: =Belgium!X12 | M13: =Belgium!X13 | N13: =Belgium!X14 | O13: =Belgium!X15 | P13: =Belgium!X16 | Q13: =Belgium!X17 | R13: =Belgium!X18 | S13: =Belgium!X19 | T13: =Belgium!X20 | U13: =Belgium!X21 | V13: =Belgium!X22 | W13: =Belgium!X23 | Y13: UNKNOWN 3 | Z13: =M26 -> 0
A14: Hungary | B14: =Hungary!X2 | C14: =Hungary!X3 | D14: =Hungary!X4 | E14: =Hungary!X5 | F14: =Hungary!X6 | G14: =Hungary!X7 | H14: =Hungary!X8 | I14: =Hungary!X9 | J14: =Hungary!X10 | K14: =Hungary!X11 | L14: =Hungary!X12 | M14: =Hungary!X13 | N14: =Hungary!X14 | O14: =Hungary!X15 | P14: =Hungary!X16 | Q14: =Hungary!X17 | R14: =Hungary!X18 | S14: =Hungary!X19 | T14: =Hungary!X20 | U14: =Hungary!X21 | V14: =Hungary!X22 | W14: =Hungary!X23 | Y14: Bearman | Z14: =N26 -> 0
A15: Netherlands | B15: =Netherlands!X2 | C15: =Netherlands!X3 | D15: =Netherlands!X4 | E15: =Netherlands!X5 | F15: =Netherlands!X6 | G15: =Netherlands!X7 | H15: =Netherlands!X8 | I15: =Netherlands!X9 | J15: =Netherlands!X10 | K15: =Netherlands!X11 | L15: =Netherlands!X12 | M15: =Netherlands!X13 | N15: =Netherlands!X14 | O15: =Netherlands!X15 | P15: =Netherlands!X16 | Q15: =Netherlands!X17 | R15: =Netherlands!X18 | S15: =Netherlands!X19 | T15: =Netherlands!X20 | U15: =Netherlands!X21 | V15: =Netherlands!X22 | W15: =Netherlands!X23 | Y15: Ocon | Z15: =O26 -> 0
A16: Italy | B16: =Italy!X2 | C16: =Italy!X3 | D16: =Italy!X4 | E16: =Italy!X5 | F16: =Italy!X6 | G16: =Italy!X7 | H16: =Italy!X8 | I16: =Italy!X9 | J16: =Italy!X10 | K16: =Italy!X11 | L16: =Italy!X12 | M16: =Italy!X13 | N16: =Italy!X14 | O16: =Italy!X15 | P16: =Italy!X16 | Q16: =Italy!X17 | R16: =Italy!X18 | S16: =Italy!X19 | T16: =Italy!X20 | U16: =Italy!X21 | V16: =Italy!X22 | W16: =Italy!X23 | Y16: Alonso | Z16: =P26 -> 0
A17: Madrid | B17: =Spain!X2 | C17: =Spain!X3 | D17: =Spain!X4 | E17: =Spain!X5 | F17: =Spain!X6 | G17: =Spain!X7 | H17: =Spain!X8 | I17: =Spain!X9 | J17: =Spain!X10 | K17: =Spain!X11 | L17: =Spain!X12 | M17: =Spain!X13 | N17: =Spain!X14 | O17: =Spain!X15 | P17: =Spain!X16 | Q17: =Spain!X17 | R17: =Spain!X18 | S17: =Spain!X19 | T17: =Spain!X20 | U17: =Spain!X21 | V17: =Spain!X22 | W17: =Spain!X23 | Y17: Stroll | Z17: =Q26 -> 0
A18: Azerbaijan | B18: =Azerbaijan!X2 | C18: =Azerbaijan!X3 | D18: =Azerbaijan!X4 | E18: =Azerbaijan!X5 | F18: =Azerbaijan!X6 | G18: =Azerbaijan!X7 | H18: =Azerbaijan!X8 | I18: =Azerbaijan!X9 | J18: =Azerbaijan!X10 | K18: =Azerbaijan!X11 | L18: =Azerbaijan!X12 | M18: =Azerbaijan!X13 | N18: =Azerbaijan!X14 | O18: =Azerbaijan!X15 | P18: =Azerbaijan!X16 | Q18: =Azerbaijan!X17 | R18: =Azerbaijan!X18 | S18: =Azerbaijan!X19 | T18: =Azerbaijan!X20 | U18: =Azerbaijan!X21 | V18: =Azerbaijan!X22 | W18: =Azerbaijan!X23 | Y18: Hulkenberg | Z18: =R26 -> 0
A19: Singapore | B19: =Singapore!X2 | C19: =Singapore!X3 | D19: =Singapore!X4 | E19: =Singapore!X5 | F19: =Singapore!X6 | G19: =Singapore!X7 | H19: =Singapore!X8 | I19: =Singapore!X9 | J19: =Singapore!X10 | K19: =Singapore!X11 | L19: =Singapore!X12 | M19: =Singapore!X13 | N19: =Singapore!X14 | O19: =Singapore!X15 | P19: =Singapore!X16 | Q19: =Singapore!X17 | R19: =Singapore!X18 | S19: =Singapore!X19 | T19: =Singapore!X20 | U19: =Singapore!X21 | V19: =Singapore!X22 | W19: =Singapore!X23 | Y19: Bortoleto | Z19: =S26 -> 0
A20: Texas | B20: =Texas!X2 | C20: =Texas!X3 | D20: =Texas!X4 | E20: =Texas!X5 | F20: =Texas!X6 | G20: =Texas!X7 | H20: =Texas!X8 | I20: =Texas!X9 | J20: =Texas!X10 | K20: =Texas!X11 | L20: =Texas!X12 | M20: =Texas!X13 | N20: =Texas!X14 | O20: =Texas!X15 | P20: =Texas!X16 | Q20: =Texas!X17 | R20: =Texas!X18 | S20: =Texas!X19 | T20: =Texas!X20 | U20: =Texas!X21 | V20: =Texas!X22 | W20: =Texas!X23 | Y20: Gasly | Z20: =T26 -> 0
A21: Mexico | B21: =Mexico!X2 | C21: =Mexico!X3 | D21: =Mexico!X4 | E21: =Mexico!X5 | F21: =Mexico!X6 | G21: =Mexico!X7 | H21: =Mexico!X8 | I21: =Mexico!X9 | J21: =Mexico!X10 | K21: =Mexico!X11 | L21: =Mexico!X12 | M21: =Mexico!X13 | N21: =Mexico!X14 | O21: =Mexico!X15 | P21: =Mexico!X16 | Q21: =Mexico!X17 | R21: =Mexico!X18 | S21: =Mexico!X19 | T21: =Mexico!X20 | U21: =Mexico!X21 | V21: =Mexico!X22 | W21: =Mexico!X23 | Y21: Colapinto | Z21: =U26 -> 0
A22: Brazil | B22: =Brazil!X2 | C22: =Brazil!X3 | D22: =Brazil!X4 | E22: =Brazil!X5 | F22: =Brazil!X6 | G22: =Brazil!X7 | H22: =Brazil!X8 | I22: =Brazil!X9 | J22: =Brazil!X10 | K22: =Brazil!X11 | L22: =Brazil!X12 | M22: =Brazil!X13 | N22: =Brazil!X14 | O22: =Brazil!X15 | P22: =Brazil!X16 | Q22: =Brazil!X17 | R22: =Brazil!X18 | S22: =Brazil!X19 | T22: =Brazil!X20 | U22: =Brazil!X21 | V22: =Brazil!X22 | W22: =Brazil!X23 | Y22: Bottas | Z22: =V26 -> 0
A23: Las Vegas | B23: ='Las Vegas'!X2 | C23: ='Las Vegas'!X3 | D23: ='Las Vegas'!X4 | E23: ='Las Vegas'!X5 | F23: ='Las Vegas'!X6 | G23: ='Las Vegas'!X7 | H23: ='Las Vegas'!X8 | I23: ='Las Vegas'!X9 | J23: ='Las Vegas'!X10 | K23: ='Las Vegas'!X11 | L23: ='Las Vegas'!X12 | M23: ='Las Vegas'!X13 | N23: ='Las Vegas'!X14 | O23: ='Las Vegas'!X15 | P23: ='Las Vegas'!X16 | Q23: ='Las Vegas'!X17 | R23: ='Las Vegas'!X18 | S23: ='Las Vegas'!X19 | T23: ='Las Vegas'!X20 | U23: ='Las Vegas'!X21 | V23: ='Las Vegas'!X22 | W23: ='Las Vegas'!X23 | Y23: Perez | Z23: =W26 -> 0
A24: Qatar | B24: =Qatar!X2 | C24: =Qatar!X3 | D24: =Qatar!X4 | E24: =Qatar!X5 | F24: =Qatar!X6 | G24: =Qatar!X7 | H24: =Qatar!X8 | I24: =Qatar!X9 | J24: =Qatar!X10 | K24: =Qatar!X11 | L24: =Qatar!X12 | M24: =Qatar!X13 | N24: =Qatar!X14 | O24: =Qatar!X15 | P24: =Qatar!X16 | Q24: =Qatar!X17 | R24: =Qatar!X18 | S24: =Qatar!X19 | T24: =Qatar!X20 | U24: =Qatar!X21 | V24: =Qatar!X22 | W24: =Qatar!X23
A25: Abu Dhabi | B25: ='Abu Dhabi'!X2 | C25: ='Abu Dhabi'!X3 | D25: ='Abu Dhabi'!X4 | E25: ='Abu Dhabi'!X5 | F25: ='Abu Dhabi'!X6 | G25: ='Abu Dhabi'!X7 | H25: ='Abu Dhabi'!X8 | I25: ='Abu Dhabi'!X9 | J25: ='Abu Dhabi'!X10 | K25: ='Abu Dhabi'!X11 | L25: ='Abu Dhabi'!X12 | M25: ='Abu Dhabi'!X13 | N25: ='Abu Dhabi'!X14 | O25: ='Abu Dhabi'!X15 | P25: ='Abu Dhabi'!X16 | Q25: ='Abu Dhabi'!X17 | R25: ='Abu Dhabi'!X18 | S25: ='Abu Dhabi'!X19 | T25: ='Abu Dhabi'!X20 | U25: ='Abu Dhabi'!X21 | V25: ='Abu Dhabi'!X22 | W25: ='Abu Dhabi'!X23
A26: Total Points | B26: =SUM(B2:B25) -> 0 | C26: =SUM(C2:C25) -> 0 | D26: =SUM(D2:D25) -> 0 | E26: =SUM(E2:E25) -> 0 | F26: =SUM(F2:F25) -> 0 | G26: =SUM(G2:G25) -> 0 | H26: =SUM(H2:H25) -> 0 | I26: =SUM(I2:I25) -> 0 | ... W26: =SUM(W2:W25) -> 0

Sheet Races
A1: Race | B1: P1 | C1: P2 | D1: P3 | E1: Pole Position | F1: Fastest Lap | G1: Fastest Pitstop | H1: # Safety Cars | I1: DNFs
A2: Australia | B2: =Australia!F18 | C2: =Australia!E18 | D2: =Australia!G18 | E2: =Australia!F19 | F2: =Australia!F20 | G2: =Australia!F21 | H2: =Australia!F22 | I2: =Australia!F23
A3: China | B3: =China!F18 | C3: =China!E18 | D3: =China!G18 | E3: =China!F19 | F3: =China!F20 | G3: =China!F21 | H3: =China!F22 | I3: =China!F23
A4: Japan | B4: =Japan!F18 | C4: =Japan!E18 | D4: =Japan!G18 | E4: =Japan!F19 | F4: =Japan!F20 | G4: =Japan!F21 | H4: =Japan!F22 | I4: =Japan!F23
A5: Bahrain | B5: =Bahrain!F18 | C5: =Bahrain!E18 | D5: =Bahrain!G18 | E5: =Bahrain!F19 | F5: =Bahrain!F20 | G5: =Bahrain!F21 | H5: =Bahrain!F22 | I5: =Bahrain!F23
A6: Saudi Arabia | B6: ='Saudi Arabia'!F18 | C6: ='Saudi Arabia'!E18 | D6: ='Saudi Arabia'!G18 | E6: ='Saudi Arabia'!F19 | F6: ='Saudi Arabia'!F20 | G6: ='Saudi Arabia'!F21 | H6: ='Saudi Arabia'!F22 | I6: ='Saudi Arabia'!F23
A7: Miami | B7: =Miami!F18 | C7: =Miami!E18 | D7: =Miami!G18 | E7: =Miami!F19 | F7: =Miami!F20 | G7: =Miami!F21 | H7: =Miami!F22 | I7: =Miami!F23
A8: Canada | B8: =Canada!F18 | C8: =Canada!E18 | D8: =Canada!G18 | E8: =Canada!F19 | F8: =Canada!F20 | G8: =Canada!F21 | H8: =Canada!F22 | I8: =Canada!F23
A9: Monaco | B9: =Monaco!F18 | C9: =Monaco!E18 | D9: =Monaco!G18 | E9: =Monaco!F19 | F9: =Monaco!F20 | G9: =Monaco!F21 | H9: =Monaco!F22 | I9: =Monaco!F23
A10: Barcelona | B10: =Barcelona!F18 | C10: =Barcelona!E18 | D10: =Barcelona!G18 | E10: =Barcelona!F19 | F10: =Barcelona!F20 | G10: =Barcelona!F21 | H10: =Barcelona!F22 | I10: =Barcelona!F23
A11: Austria | B11: =Austria!F18 | C11: =Austria!E18 | D11: =Austria!G18 | E11: =Austria!F19 | F11: =Austria!F20 | G11: =Austria!F21 | H11: =Austria!F22 | I11: =Austria!F23
A12: Great Britain | B12: ='Great Britain'!F18 | C12: ='Great Britain'!E18 | D12: ='Great Britain'!G18 | E12: ='Great Britain'!F19 | F12: ='Great Britain'!F20 | G12: ='Great Britain'!F21 | H12: ='Great Britain'!F22 | I12: ='Great Britain'!F23
A13: Belgium | B13: =Belgium!F18 | C13: =Belgium!E18 | D13: =Belgium!G18 | E13: =Belgium!F19 | F13: =Belgium!F20 | G13: =Belgium!F21 | H13: =Belgium!F22 | I13: =Belgium!F23
A14: Hungary | B14: =Hungary!F18 | C14: =Hungary!E18 | D14: =Hungary!G18 | E14: =Hungary!F19 | F14: =Hungary!F20 | G14: =Hungary!F21 | H14: =Hungary!F22 | I14: =Hungary!F23
A15: Netherlands | B15: =Netherlands!F18 | C15: =Netherlands!E18 | D15: =Netherlands!G18 | E15: =Netherlands!F19 | F15: =Netherlands!F20 | G15: =Netherlands!F21 | H15: =Netherlands!F22 | I15: =Netherlands!F23
A16: Italy | B16: =Italy!F18 | C16: =Italy!E18 | D16: =Italy!G18 | E16: =Italy!F19 | F16: =Italy!F20 | G16: =Italy!F21 | H16: =Italy!F22 | I16: =Italy!F23
A17: Madrid | B17: =Spain!F18 | C17: =Spain!E18 | D17: =Spain!G18 | E17: =Spain!F19 | F17: =Spain!F20 | G17: =Spain!F21 | H17: =Spain!F22 | I17: =Spain!F23
A18: Azerbaijan | B18: =Azerbaijan!F18 | C18: =Azerbaijan!E18 | D18: =Azerbaijan!G18 | E18: =Azerbaijan!F19 | F18: =Azerbaijan!F20 | G18: =Azerbaijan!F21 | H18: =Azerbaijan!F22 | I18: =Azerbaijan!F23
A19: Singapore | B19: =Singapore!F18 | C19: =Singapore!E18 | D19: =Singapore!G18 | E19: =Singapore!F19 | F19: =Singapore!F20 | G19: =Singapore!F21 | H19: =Singapore!F22 | I19: =Singapore!F23
A20: Texas | B20: =Texas!F18 | C20: =Texas!E18 | D20: =Texas!G18 | E20: =Texas!F19 | F20: =Texas!F20 | G20: =Texas!F21 | H20: =Texas!F22 | I20: =Texas!F23
A21: Mexico | B21: =Mexico!F18 | C21: =Mexico!E18 | D21: =Mexico!G18 | E21: =Mexico!F19 | F21: =Mexico!F20 | G21: =Mexico!F21 | H21: =Mexico!F22 | I21: =Mexico!F23
A22: Brazil | B22: =Brazil!F18 | C22: =Brazil!E18 | D22: =Brazil!G18 | E22: =Brazil!F19 | F22: =Brazil!F20 | G22: =Brazil!F21 | H22: =Brazil!F22 | I22: =Brazil!F23
A23: Las Vegas | B23: ='Las Vegas'!F18 | C23: ='Las Vegas'!E18 | D23: ='Las Vegas'!G18 | E23: ='Las Vegas'!F19 | F23: ='Las Vegas'!F20 | G23: ='Las Vegas'!F21 | H23: ='Las Vegas'!F22 | I23: ='Las Vegas'!F23
A24: Qatar | B24: =Qatar!F18 | C24: =Qatar!E18 | D24: =Qatar!G18 | E24: =Qatar!F19 | F24: =Qatar!F20 | G24: =Qatar!F21 | H24: =Qatar!F22 | I24: =Qatar!F23
A25: Abu Dhabi | B25: ='Abu Dhabi'!F18 | C25: ='Abu Dhabi'!E18 | D25: ='Abu Dhabi'!G18 | E25: ='Abu Dhabi'!F19 | F25: ='Abu Dhabi'!F20 | G25: ='Abu Dhabi'!F21 | H25: ='Abu Dhabi'!F22 | I25: ='Abu Dhabi'!F23

Sheet Australia
A1: Dates | B1: Times (EST) | C1: Session | E1: Race Starting Grid | J1: Race Results | O1: WDC Standings | S1: WCC Standings | W1: Driver | X1: Points Earned | Y1: Qualifying Position | Z1: Race Position | AA1: Positions Gained/Lost
A2: 45721 | B2: 8:30 AM - 9:30 AM | C2: FP1 | E2: 1 | H2: 2 | J2: 1 | M2: 2 | O2: Position | P2: Driver | Q2: Points | S2: Position | T2: Team | U2: Points | W2: Lando Norris | AA2: =Y2-Z2 -> 0
A3: 45722 | B3: 12:00 AM - 1:00 AM | C3: FP2 | E3: 3 | H3: 4 | J3: 3 | M3: 4 | O3: 1 | S3: 1 | W3: Oscar Piastri | AA3: =Y3-Z3 -> 0
B4: 8:30 PM - 9:30 PM | C4: FP3 | E4: 5 | H4: 6 | J4: 5 | M4: 6 | O4: 2 | S4: 2 | W4: George Russell | AA4: =Y4-Z4 -> 0
A5: 45723 | B5: 12:00 AM - 1:00 AM | C5: Quali | E5: 7 | H5: 8 | J5: 7 | M5: 8 | O5: 3 | S5: 3 | W5: Kimi Antonelli | AA5: =Y5-Z5 -> 0
B6: 0.95833333 | C6: Race | E6: 9 | H6: 10 | J6: 9 | M6: 10 | O6: 4 | S6: 4 | W6: Max Verstappen | AA6: =Y6-Z6 -> 0
E7: 11 | H7: 12 | J7: 11 | M7: 12 | O7: 5 | S7: 5 | W7: UNKNOWN 1 | AA7: =Y7-Z7 -> 0
A8: Race Predictions | E8: 13 | H8: 14 | J8: 13 | M8: 14 | O8: 6 | S8: 6 | W8: Lewis Hamilton | AA8: =Y8-Z8 -> 0
A9: Podium | E9: 15 | H9: 16 | J9: 15 | M9: 16 | O9: 7 | S9: 7 | W9: Charles Leclerc | AA9: =Y9-Z9 -> 0
A10: 2 | B10: 1 | C10: 3 | E10: 17 | H10: 18 | J10: 17 | M10: 18 | O10: 8 | S10: 8 | W10: Carlos Sainz | AA10: =Y10-Z10 -> 0
E11: 19 | H11: 20 | J11: 19 | M11: 20 | O11: 9 | S11: 9 | W11: Alex Albon | AA11: =Y11-Z11 -> 0
A12: Pole | E12: 21 | H12: 22 | J12: 21 | M12: 22 | O12: 10 | S12: 10 | W12: UNKNOWN 2 | AA12: =Y12-Z12 -> 0
A13: Fastest Lap | E13: Pit Lane: | J13: DNF(s): | O13: 11 | S13: 11 | W13: UNKNOWN 3 | AA13: =Y13-Z13 -> 0
A14: Fastest Pitstop | E14: DNS | O14: 12 | W14: Ollie Bearman | AA14: =Y14-Z14 -> 0
A15: # Safety Cars | J15: WDC Points (Race) | O15: 13 | W15: Esteban Ocon | AA15: =Y15-Z15 -> 0
A16: DNF(s) | E16: Race Podium | J16: 25 | K16: =P3 | O16: 14 | W16: Fernando Alonso | AA16: =Y16-Z16 -> 0
A17: Flop | E17: 2 | F17: 1 | G17: 3 | J17: 18 | K17: =P4 | O17: 15 | W17: Lance Stroll | AA17: =Y17-Z17 -> 0
A18: Surprise | E18: =L2 | F18: =K2 | G18: =K3 | J18: 15 | K18: =P5 | O18: 16 | W18: Nico Hulkenberg | AA18: =Y18-Z18 -> 0
E19: Pole | F19: =F2 | J19: 12 | K19: =P6 | O19: 17 | W19: Gabriel Bortoleto | AA19: =Y19-Z19 -> 0
A20: Weather | E20: Fastest Lap | J20: 10 | K20: =P7 | O20: 18 | W20: Pierre Gasly | AA20: =Y20-Z20 -> 0
A21: FP1 | E21: Fastest Pitstop | J21: 8 | K21: =P8 | O21: 19 | W21: Franco Colapinto | AA21: =Y21-Z21 -> 0
A22: FP2 | E22: # Safety Cars | J22: 6 | K22: =P9 | O22: 20 | W22: Valterri Bottas | AA22: =Y22-Z22 -> 0
A23: FP3 | E23: DNF(s) | F23: =K13 | J23: 4 | K23: =P10 | O23: 21 | W23: Sergio Perez | AA23: =Y23-Z23 -> 0
A24: Quali | E24: DOTD | J24: 2 | K24: =P11 | O24: 22
A25: Race | J25: 1 | K25: =P12
A27: FP1
A28: 2 | B28: 1 | C28: 3
A30: FP2
A31: 2 | B31: 1 | C31: 3
A33: FP3
A34: 2 | B34: 1 | C34: 3

Sheet China
A1: Dates | B1: Times (EST) | C1: Session | E1: Race Starting Grid | J1: Race Results | O1: WDC Standings | S1: WCC Standings | W1: Driver | X1: Points Earned | Y1: Qualifying Position | Z1: Race Position | AA1: Positions Gained/Lost
A2: 45728 | B2: 11:30 PM - 12:30 AM | C2: FP1 | E2: 1 | H2: 2 | J2: 1 | M2: 2 | O2: Position | P2: Driver | Q2: Points | S2: Position | T2: Team | U2: Points | W2: Lando Norris | AA2: =Y2-Z2 -> 0
A3: 45729 | B3: 3:30 AM - 4:14 AM | C3: Sprint Quali | E3: 3 | H3: 4 | J3: 3 | M3: 4 | O3: 1 | S3: 1 | W3: Oscar Piastri | AA3: =Y3-Z3 -> 0
B4: 11:00 PM - 12:00 AM | C4: Sprint | E4: 5 | H4: 6 | J4: 5 | M4: 6 | O4: 2 | S4: 2 | W4: George Russell | AA4: =Y4-Z4 -> 0
A5: 45730 | B5: 3:00 AM - 4:00 AM | C5: Quali | E5: 7 | H5: 8 | J5: 7 | M5: 8 | O5: 3 | S5: 3 | W5: Kimi Antonelli | AA5: =Y5-Z5 -> 0
A6: 45731 | B6: 0.125 | C6: Race | E6: 9 | H6: 10 | J6: 9 | M6: 10 | O6: 4 | S6: 4 | W6: Max Verstappen | AA6: =Y6-Z6 -> 0
E7: 11 | H7: 12 | J7: 11 | M7: 12 | O7: 5 | S7: 5 | W7: UNKNOWN 1 | AA7: =Y7-Z7 -> 0
A8: Race Predictions | E8: 13 | H8: 14 | J8: 13 | M8: 14 | O8: 6 | S8: 6 | W8: Lewis Hamilton | AA8: =Y8-Z8 -> 0
A9: Podium | E9: 15 | H9: 16 | J9: 15 | M9: 16 | O9: 7 | S9: 7 | W9: Charles Leclerc | AA9: =Y9-Z9 -> 0
A10: 2 | B10: 1 | C10: 3 | E10: 17 | H10: 18 | J10: 17 | M10: 18 | O10: 8 | S10: 8 | W10: Carlos Sainz | AA10: =Y10-Z10 -> 0
E11: 19 | H11: 20 | J11: 19 | M11: 20 | O11: 9 | S11: 9 | W11: Alex Albon | AA11: =Y11-Z11 -> 0
A12: Pole | E12: 21 | H12: 22 | J12: 21 | M12: 22 | O12: 10 | S12: 10 | W12: UNKNOWN 2 | AA12: =Y12-Z12 -> 0
A13: Fastest Lap | E13: Pit Lane: | J13: DNF(s): | O13: 11 | S13: 11 | W13: UNKNOWN 3 | AA13: =Y13-Z13 -> 0
A14: Fastest Pitstop | E14: DNS | O14: 12 | W14: Ollie Bearman | AA14: =Y14-Z14 -> 0
A15: # Safety Cars | J15: WDC Points (Race) | O15: 13 | W15: Esteban Ocon | AA15: =Y15-Z15 -> 0
A16: DNF(s) | E16: Race Podium | J16: 25 | O16: 14 | W16: Fernando Alonso | AA16: =Y16-Z16 -> 0
A17: Flop | E17: 2 | F17: 1 | G17: 3 | J17: 18 | O17: 15 | W17: Lance Stroll | AA17: =Y17-Z17 -> 0
A18: Surprise | E18: =L2 | F18: =K2 | G18: =K3 | J18: 15 | O18: 16 | W18: Nico Hulkenberg | AA18: =Y18-Z18 -> 0
E19: Pole | F19: =F2 | J19: 12 | O19: 17 | W19: Gabriel Bortoleto | AA19: =Y19-Z19 -> 0
A20: Weather | E20: Fastest Lap | J20: 10 | O20: 18 | W20: Pierre Gasly | AA20: =Y20-Z20 -> 0
A21: FP1 | E21: Fastest Pitstop | J21: 8 | O21: 19 | W21: Franco Colapinto | AA21: =Y21-Z21 -> 0
A22: Sprint Quali | E22: # Safety Cars | J22: 6 | O22: 20 | W22: Valterri Bottas | AA22: =Y22-Z22 -> 0
A23: Sprint | E23: DNF(s) | F23: =K13 | J23: 4 | O23: 21 | W23: Sergio Perez | AA23: =Y23-Z23 -> 0
A24: Quali | E24: DOTD | J24: 2 | O24: 22
A25: Race | J25: 1
A27: Sprint Predictions | E27: Sprint Starting Grid | J27: Sprint Results
A28: Podium | E28: 1 | H28: 2 | J28: 1 | M28: 2
A29: 2 | B29: 1 | C29: 3 | E29: 3 | H29: 4 | J29: 3 | M29: 4
E30: 5 | H30: 6 | J30: 5 | M30: 6
A31: Pole | E31: 7 | H31: 8 | J31: 7 | M31: 8
A32: Fastest Lap | E32: 9 | H32: 10 | J32: 9 | M32: 10
A33: Fastest Pitstop | E33: 11 | H33: 12 | J33: 11 | M33: 12
A34: # Safety Cars | E34: 13 | H34: 14 | J34: 13 | M34: 14
A35: DNF(s) | E35: 15 | H35: 16 | J35: 15 | M35: 16
A36: Flop | E36: 17 | H36: 18 | J36: 17 | M36: 18
A37: Surprise | E37: 19 | H37: 20 | J37: 19 | M37: 20
E38: 21 | H38: 22 | J38: 21 | M38: 22
A39: FP1 | E39: Pit Lane: | J39: DNF(s):
A40: 2 | B40: 1 | C40: 3 | E40: DNS
A42: FP2 | E42: Sprint Podium | J42: WDC Points (Sprint)
...

Sheet Japan
A1: Dates | B1: Times (EST) | C1: Session | E1: Race Starting Grid | J1: Race Results | O1: WDC Standings | S1: WCC Standings | W1: Driver | X1: Points Earned | Y1: Qualifying Position | Z1: Race Position | AA1: Positions Gained/Lost
A2: 45742 | B2: 10:30 PM - 11:30 PM | C2: FP1 | E2: 1 | H2: 2 | J2: 1 | M2: 2 | O2: Position | P2: Driver | Q2: Points | S2: Position | T2: Team | U2: Points | W2: Lando Norris | AA2: =Y2-Z2 -> 0
A3: 45743 | B3: 2:00 AM - 3:00 AM | C3: FP2 | E3: 3 | H3: 4 | J3: 3 | M3: 4 | O3: 1 | S3: 1 | W3: Oscar Piastri | AA3: =Y3-Z3 -> 0
B4: 10:30 PM - 11:30 PM | C4: FP3 | E4: 5 | H4: 6 | J4: 5 | M4: 6 | O4: 2 | S4: 2 | W4: George Russell | AA4: =Y4-Z4 -> 0
A5: 45744 | B5: 2:00 AM - 3:00 AM | C5: Quali | E5: 7 | H5: 8 | J5: 7 | M5: 8 | O5: 3 | S5: 3 | W5: Kimi Antonelli | AA5: =Y5-Z5 -> 0
A6: 45745 | B6: 0.041666667 | C6: Race | E6: 9 | H6: 10 | J6: 9 | M6: 10 | O6: 4 | S6: 4 | W6: Max Verstappen | AA6: =Y6-Z6 -> 0
E7: 11 | H7: 12 | J7: 11 | M7: 12 | O7: 5 | S7: 5 | W7: UNKNOWN 1 | AA7: =Y7-Z7 -> 0
A8: Race Predictions | E8: 13 | H8: 14 | J8: 13 | M8: 14 | O8: 6 | S8: 6 | W8: Lewis Hamilton | AA8: =Y8-Z8 -> 0
A9: Podium | E9: 15 | H9: 16 | J9: 15 | M9: 16 | O9: 7 | S9: 7 | W9: Charles Leclerc | AA9: =Y9-Z9 -> 0
A10: 2 | B10: 1 | C10: 3 | E10: 17 | H10: 18 | J10: 17 | M10: 18 | O10: 8 | S10: 8 | W10: Carlos Sainz | AA10: =Y10-Z10 -> 0
E11: 19 | H11: 20 | J11: 19 | M11: 20 | O11: 9 | S11: 9 | W11: Alex Albon | AA11: =Y11-Z11 -> 0
A12: Pole | E12: 21 | H12: 22 | J12: 21 | M12: 22 | O12: 10 | S12: 10 | W12: UNKNOWN 2 | AA12: =Y12-Z12 -> 0
A13: Fastest Lap | E13: Pit Lane: | J13: DNF(s): | O13: 11 | S13: 11 | W13: UNKNOWN 3 | AA13: =Y13-Z13 -> 0
A14: Fastest Pitstop | E14: DNS | O14: 12 | W14: Ollie Bearman | AA14: =Y14-Z14 -> 0
A15: # Safety Cars | O15: 13 | W15: Esteban Ocon | AA15: =Y15-Z15 -> 0
A16: DNF(s) | E16: Race Podium | J16: WDC Points (Race) | O16: 14 | W16: Fernando Alonso | AA16: =Y16-Z16 -> 0
A17: Flop | E17: 2 | F17: 1 | G17: 3 | J17: 25 | O17: 15 | W17: Lance Stroll | AA17: =Y17-Z17 -> 0
A18: Surprise | E18: =L2 | F18: =K2 | G18: =K3 | J18: 18 | O18: 16 | W18: Nico Hulkenberg | AA18: =Y18-Z18 -> 0
E19: Pole | F19: =F2 | J19: 15 | O19: 17 | W19: Gabriel Bortoleto | AA19: =Y19-Z19 -> 0
A20: Weather | E20: Fastest Lap | J20: 12 | O20: 18 | W20: Pierre Gasly | AA20: =Y20-Z20 -> 0
A21: FP1 | E21: Fastest Pitstop | J21: 10 | O21: 19 | W21: Franco Colapinto | AA21: =Y21-Z21 -> 0
A22: FP2 | E22: # Safety Cars | J22: 8 | O22: 20 | W22: Valterri Bottas | AA22: =Y22-Z22 -> 0
A23: FP3 | E23: DNF(s) | F23: =K13 | J23: 6 | O23: 21 | W23: Sergio Perez | AA23: =Y23-Z23 -> 0
A24: Quali | E24: DOTD | J24: 4 | O24: 22
A25: Race | J25: 2
J26: 1
A27: FP1
A28: 2 | B28: 1 | C28: 3
A30: FP2
A31: 2 | B31: 1 | C31: 3
A33: FP3
A34: 2 | B34: 1 | C34: 3

Sheet Bahrain
A1: Dates | B1: Times (EST) | C1: Session | E1: Race Starting Grid | J1: Race Results | O1: WDC Standings | S1: WCC Standings | W1: Driver | X1: Points Earned | Y1: Qualifying Position | Z1: Race Position | AA1: Positions Gained/Lost
A2: 45757 | B2: 7:30 AM - 8:30 AM | C2: FP1 | E2: 1 | H2: 2 | J2: 1 | M2: 2 | O2: Position | P2: Driver | Q2: Points | S2: Position | T2: Team | U2: Points | W2: Lando Norris | AA2: =Y2-Z2 -> 0
B3: 11:00 AM - 12:00 PM | C3: FP2 | E3: 3 | H3: 4 | J3: 3 | M3: 4 | O3: 1 | S3: 1 | W3: Oscar Piastri | AA3: =Y3-Z3 -> 0
A4: 45758 | B4: 8:30 AM - 9:30 AM | C4: FP3 | E4: 5 | H4: 6 | J4: 5 | M4: 6 | O4: 2 | S4: 2 | W4: George Russell | AA4: =Y4-Z4 -> 0
B5: 12:00 PM - 1:00 PM | C5: Quali | E5: 7 | H5: 8 | J5: 7 | M5: 8 | O5: 3 | S5: 3 | W5: Kimi Antonelli | AA5: =Y5-Z5 -> 0
A6: 45759 | B6: 0.45833333 | C6: Race | E6: 9 | H6: 10 | J6: 9 | M6: 10 | O6: 4 | S6: 4 | W6: Max Verstappen | AA6: =Y6-Z6 -> 0
E7: 11 | H7: 12 | J7: 11 | M7: 12 | O7: 5 | S7: 5 | W7: UNKNOWN 1 | AA7: =Y7-Z7 -> 0
A8: Race Predictions | E8: 13 | H8: 14 | J8: 13 | M8: 14 | O8: 6 | S8: 6 | W8: Lewis Hamilton | AA8: =Y8-Z8 -> 0
A9: Podium | E9: 15 | H9: 16 | J9: 15 | M9: 16 | O9: 7 | S9: 7 | W9: Charles Leclerc | AA9: =Y9-Z9 -> 0
A10: 2 | B10: 1 | C10: 3 | E10: 17 | H10: 18 | J10: 17 | M10: 18 | O10: 8 | S10: 8 | W10: Carlos Sainz | AA10: =Y10-Z10 -> 0
E11: 19 | H11: 20 | J11: 19 | M11: 20 | O11: 9 | S11: 9 | W11: Alex Albon | AA11: =Y11-Z11 -> 0
A12: Pole | E12: 21 | H12: 22 | J12: 21 | M12: 22 | O12: 10 | S12: 10 | W12: UNKNOWN 2 | AA12: =Y12-Z12 -> 0
A13: Fastest Lap | E13: Pit Lane: | J13: DNF(s): | O13: 11 | S13: 11 | W13: UNKNOWN 3 | AA13: =Y13-Z13 -> 0
A14: Fastest Pitstop | E14: DNS | O14: 12 | W14: Ollie Bearman | AA14: =Y14-Z14 -> 0
A15: # Safety Cars | J15: WDC Points (Race) | O15: 13 | W15: Esteban Ocon | AA15: =Y15-Z15 -> 0
A16: DNF(s) | E16: Race Podium | J16: 25 | O16: 14 | W16: Fernando Alonso | AA16: =Y16-Z16 -> 0
A17: Flop | E17: 2 | F17: 1 | G17: 3 | J17: 18 | O17: 15 | W17: Lance Stroll | AA17: =Y17-Z17 -> 0
A18: Surprise | E18: =L2 | F18: =K2 | G18: =K3 | J18: 15 | O18: 16 | W18: Nico Hulkenberg | AA18: =Y18-Z18 -> 0
E19: Pole | F19: =F2 | J19: 12 | O19: 17 | W19: Gabriel Bortoleto | AA19: =Y19-Z19 -> 0
A20: Weather | E20: Fastest Lap | J20: 10 | O20: 18 | W20: Pierre Gasly | AA20: =Y20-Z20 -> 0
A21: FP1 | E21: Fastest Pitstop | J21: 8 | O21: 19 | W21: Franco Colapinto | AA21: =Y21-Z21 -> 0
A22: FP2 | E22: # Safety Cars | J22: 6 | O22: 20 | W22: Valterri Bottas | AA22: =Y22-Z22 -> 0
A23: FP3 | E23: DNF(s) | F23: =K13 | J23: 4 | O23: 21 | W23: Sergio Perez | AA23: =Y23-Z23 -> 0
A24: Quali | E24: DOTD | J24: 2 | O24: 22
A25: Race | J25: 1
A27: FP1
A28: 2 | B28: 1 | C28: 3
A30: FP2
A31: 2 | B31: 1 | C31: 3
A33: FP3
A34: 2 | B34: 1 | C34: 3

Sheet Saudi Arabia
A1: Dates | B1: Times (EST) | C1: Session | E1: Race Starting Grid | J1: Race Results | O1: WDC Standings | S1: WCC Standings | W1: Driver | X1: Points Earned | Y1: Qualifying Position | Z1: Race Position | AA1: Positions Gained/Lost
A2: 45764 | B2: 9:30 AM - 10:30 AM | C2: FP1 | E2: 1 | H2: 2 | J2: 1 | M2: 2 | O2: Position | P2: Driver | Q2: Points | S2: Position | T2: Team | U2: Points | W2: Lando Norris | AA2: =Y2-Z2 -> 0
B3: 1:00 PM - 2:00 PM | C3: FP2 | E3: 3 | H3: 4 | J3: 3 | M3: 4 | O3: 1 | S3: 1 | W3: Oscar Piastri | AA3: =Y3-Z3 -> 0
A4: 45765 | B4: 9:30 AM - 10:30 AM | C4: FP3 | E4: 5 | H4: 6 | J4: 5 | M4: 6 | O4: 2 | S4: 2 | W4: George Russell | AA4: =Y4-Z4 -> 0
B5: 1:00 PM - 2:00 PM | C5: Quali | E5: 7 | H5: 8 | J5: 7 | M5: 8 | O5: 3 | S5: 3 | W5: Kimi Antonelli | AA5: =Y5-Z5 -> 0
A6: 45766 | B6: 0.54166667 | C6: Race | E6: 9 | H6: 10 | J6: 9 | M6: 10 | O6: 4 | S6: 4 | W6: Max Verstappen | AA6: =Y6-Z6 -> 0
E7: 11 | H7: 12 | J7: 11 | M7: 12 | O7: 5 | S7: 5 | W7: UNKNOWN 1 | AA7: =Y7-Z7 -> 0
A8: Race Predictions | E8: 13 | H8: 14 | J8: 13 | M8: 14 | O8: 6 | S8: 6 | W8: Lewis Hamilton | AA8: =Y8-Z8 -> 0
A9: Podium | E9: 15 | H9: 16 | J9: 15 | M9: 16 | O9: 7 | S9: 7 | W9: Charles Leclerc | AA9: =Y9-Z9 -> 0
A10: 2 | B10: 1 | C10: 3 | E10: 17 | H10: 18 | J10: 17 | M10: 18 | O10: 8 | S10: 8 | W10: Carlos Sainz | AA10: =Y10-Z10 -> 0
E11: 19 | H11: 20 | J11: 19 | M11: 20 | O11: 9 | S11: 9 | W11: Alex Albon | AA11: =Y11-Z11 -> 0
A12: Pole | E12: 21 | H12: 22 | J12: 21 | M12: 22 | O12: 10 | S12: 10 | W12: UNKNOWN 2 | AA12: =Y12-Z12 -> 0
A13: Fastest Lap | E13: Pit Lane: | J13: DNF(s): | O13: 11 | S13: 11 | W13: UNKNOWN 3 | AA13: =Y13-Z13 -> 0
A14: Fastest Pitstop | E14: DNS | O14: 12 | W14: Ollie Bearman | AA14: =Y14-Z14 -> 0
A15: # Safety Cars | J15: WDC Points (Race) | O15: 13 | W15: Esteban Ocon | AA15: =Y15-Z15 -> 0
A16: DNF(s) | E16: Race Podium | J16: 25 | O16: 14 | W16: Fernando Alonso | AA16: =Y16-Z16 -> 0
A17: Flop | E17: 2 | F17: 1 | G17: 3 | J17: 18 | O17: 15 | W17: Lance Stroll | AA17: =Y17-Z17 -> 0
A18: Surprise | E18: =L2 | F18: =K2 | G18: =K3 | J18: 15 | O18: 16 | W18: Nico Hulkenberg | AA18: =Y18-Z18 -> 0
E19: Pole | F19: =F2 | J19: 12 | O19: 17 | W19: Gabriel Bortoleto | AA19: =Y19-Z19 -> 0
A20: Weather | E20: Fastest Lap | J20: 10 | O20: 18 | W20: Pierre Gasly | AA20: =Y20-Z20 -> 0
A21: FP1 | E21: Fastest Pitstop | J21: 8 | O21: 19 | W21: Franco Colapinto | AA21: =Y21-Z21 -> 0
A22: FP2 | E22: # Safety Cars | J22: 6 | O22: 20 | W22: Valterri Bottas | AA22: =Y22-Z22 -> 0
A23: FP3 | E23: DNF(s) | F23: =K13 | J23: 4 | O23: 21 | W23: Sergio Perez | AA23: =Y23-Z23 -> 0
A24: Quali | E24: DOTD | J24: 2 | O24: 22
A25: Race | J25: 1
A27: FP1
A28: 2 | B28: 1 | C28: 3
A30: FP2
A31: 2 | B31: 1 | C31: 3
A33: FP3
A34: 2 | B34: 1 | C34: 3

Sheet Miami
A1: Dates | B1: Times (EST) | C1: Session | E1: Race Starting Grid | J1: Race Results | O1: WDC Standings | S1: WCC Standings | W1: Driver | X1: Points Earned | Y1: Qualifying Position | Z1: Race Position | AA1: Positions Gained/Lost
A2: 45778 | B2: 12:30 PM - 1:30 PM | C2: FP1 | E2: 1 | H2: 2 | J2: 1 | M2: 2 | O2: Position | P2: Driver | Q2: Points | S2: Position | T2: Team | U2: Points | W2: Lando Norris | AA2: =Y2-Z2 -> 0
B3: 4:30 PM - 5:14 PM | C3: Sprint Quali | E3: 3 | H3: 4 | J3: 3 | M3: 4 | O3: 1 | S3: 1 | W3: Oscar Piastri | AA3: =Y3-Z3 -> 0
A4: 45779 | B4: 12:00 PM - 1:00 PM | C4: Sprint | E4: 5 | H4: 6 | J4: 5 | M4: 6 | O4: 2 | S4: 2 | W4: George Russell | AA4: =Y4-Z4 -> 0
B5: 4:00 PM - 5:00 PM | C5: Quali | E5: 7 | H5: 8 | J5: 7 | M5: 8 | O5: 3 | S5: 3 | W5: Kimi Antonelli | AA5: =Y5-Z5 -> 0
A6: 45780 | B6: 0.66666667 | C6: Race | E6: 9 | H6: 10 | J6: 9 | M6: 10 | O6: 4 | S6: 4 | W6: Max Verstappen | AA6: =Y6-Z6 -> 0
E7: 11 | H7: 12 | J7: 11 | M7: 12 | O7: 5 | S7: 5 | W7: UNKNOWN 1 | AA7: =Y7-Z7 -> 0
A8: Race Predictions | E8: 13 | H8: 14 | J8: 13 | M8: 14 | O8: 6 | S8: 6 | W8: Lewis Hamilton | AA8: =Y8-Z8 -> 0
A9: Podium | E9: 15 | H9: 16 | J9: 15 | M9: 16 | O9: 7 | S9: 7 | W9: Charles Leclerc | AA9: =Y9-Z9 -> 0
A10: 2 | B10: 1 | C10: 3 | E10: 17 | H10: 18 | J10: 17 | M10: 18 | O10: 8 | S10: 8 | W10: Carlos Sainz | AA10: =Y10-Z10 -> 0
E11: 19 | H11: 20 | J11: 19 | M11: 20 | O11: 9 | S11: 9 | W11: Alex Albon | AA11: =Y11-Z11 -> 0
A12: Pole | E12: 21 | H12: 22 | J12: 21 | M12: 22 | O12: 10 | S12: 10 | W12: UNKNOWN 2 | AA12: =Y12-Z12 -> 0
A13: Fastest Lap | E13: Pit Lane: | J13: DNF(s): | O13: 11 | S13: 11 | W13: UNKNOWN 3 | AA13: =Y13-Z13 -> 0
A14: Fastest Pitstop | E14: DNS | O14: 12 | W14: Ollie Bearman | AA14: =Y14-Z14 -> 0
A15: # Safety Cars | J15: WDC Points (Race) | O15: 13 | W15: Esteban Ocon | AA15: =Y15-Z15 -> 0
A16: DNF(s) | E16: Race Podium | J16: 25 | O16: 14 | W16: Fernando Alonso | AA16: =Y16-Z16 -> 0
A17: Flop | E17: 2 | F17: 1 | G17: 3 | J17: 18 | O17: 15 | W17: Lance Stroll | AA17: =Y17-Z17 -> 0
A18: Surprise | E18: =L2 | F18: =K2 | G18: =K3 | J18: 15 | O18: 16 | W18: Nico Hulkenberg | AA18: =Y18-Z18 -> 0
E19: Pole | F19: =F2 | J19: 12 | O19: 17 | W19: Gabriel Bortoleto | AA19: =Y19-Z19 -> 0
A20: Weather | E20: Fastest Lap | J20: 10 | O20: 18 | W20: Pierre Gasly | AA20: =Y20-Z20 -> 0
A21: FP1 | E21: Fastest Pitstop | J21: 8 | O21: 19 | W21: Franco Colapinto | AA21: =Y21-Z21 -> 0
A22: Sprint Quali | E22: # Safety Cars | J22: 6 | O22: 20 | W22: Valterri Bottas | AA22: =Y22-Z22 -> 0
A23: Sprint | E23: DNF(s) | F23: =K13 | J23: 4 | O23: 21 | W23: Sergio Perez | AA23: =Y23-Z23 -> 0
A24: Quali | E24: DOTD | J24: 2 | O24: 22
A25: Race | J25: 1
A27: Sprint Predictions | E27: Sprint Starting Grid | J27: Sprint Results
A28: Podium | E28: 1 | H28: 2 | J28: 1 | M28: 2
A29: 2 | B29: 1 | C29: 3 | E29: 3 | H29: 4 | J29: 3 | M29: 4
E30: 5 | H30: 6 | J30: 5 | M30: 6
A31: Pole | E31: 7 | H31: 8 | J31: 7 | M31: 8
A32: Fastest Lap | E32: 9 | H32: 10 | J32: 9 | M32: 10
A33: Fastest Pitstop | E33: 11 | H33: 12 | J33: 11 | M33: 12
A34: # Safety Cars | E34: 13 | H34: 14 | J34: 13 | M34: 14
A35: DNF(s) | E35: 15 | H35: 16 | J35: 15 | M35: 16
A36: Flop | E36: 17 | H36: 18 | J36: 17 | M36: 18
A37: Surprise | E37: 19 | H37: 20 | J37: 19 | M37: 20
E38: 21 | H38: 22 | J38: 21 | M38: 22
A39: FP1 | E39: Pit Lane: | J39: DNF(s):
A40: 2 | B40: 1 | C40: 3 | E40: DNS
A42: FP2 | E42: Sprint Podium | J42: WDC Points (Sprint)
...

Sheet Canada
A1: Dates | B1: Times (EST) | C1: Session | E1: Race Starting Grid | J1: Race Results | O1: WDC Standings | S1: WCC Standings | W1: Driver | X1: Points Earned | Y1: Qualifying Position | Z1: Race Position | AA1: Positions Gained/Lost
A2: 45799 | B2: 12:30 PM - 1:30 PM | C2: FP1 | E2: 1 | H2: 2 | J2: 1 | M2: 2 | O2: Position | P2: Driver | Q2: Points | S2: Position | T2: Team | U2: Points | W2: Lando Norris | AA2: =Y2-Z2 -> 0
B3: 4:30 PM - 5:14 PM | C3: Sprint Quali | E3: 3 | H3: 4 | J3: 3 | M3: 4 | O3: 1 | S3: 1 | W3: Oscar Piastri | AA3: =Y3-Z3 -> 0
A4: 45800 | B4: 12:00 PM - 1:00 PM | C4: Sprint | E4: 5 | H4: 6 | J4: 5 | M4: 6 | O4: 2 | S4: 2 | W4: George Russell | AA4: =Y4-Z4 -> 0
B5: 4:00 PM - 5:00 PM | C5: Quali | E5: 7 | H5: 8 | J5: 7 | M5: 8 | O5: 3 | S5: 3 | W5: Kimi Antonelli | AA5: =Y5-Z5 -> 0
A6: 45801 | B6: 0.66666667 | C6: Race | E6: 9 | H6: 10 | J6: 9 | M6: 10 | O6: 4 | S6: 4 | W6: Max Verstappen | AA6: =Y6-Z6 -> 0
E7: 11 | H7: 12 | J7: 11 | M7: 12 | O7: 5 | S7: 5 | W7: UNKNOWN 1 | AA7: =Y7-Z7 -> 0
A8: Race Predictions | E8: 13 | H8: 14 | J8: 13 | M8: 14 | O8: 6 | S8: 6 | W8: Lewis Hamilton | AA8: =Y8-Z8 -> 0
A9: Podium | E9: 15 | H9: 16 | J9: 15 | M9: 16 | O9: 7 | S9: 7 | W9: Charles Leclerc | AA9: =Y9-Z9 -> 0
A10: 2 | B10: 1 | C10: 3 | E10: 17 | H10: 18 | J10: 17 | M10: 18 | O10: 8 | S10: 8 | W10: Carlos Sainz | AA10: =Y10-Z10 -> 0
E11: 19 | H11: 20 | J11: 19 | M11: 20 | O11: 9 | S11: 9 | W11: Alex Albon | AA11: =Y11-Z11 -> 0
A12: Pole | E12: 21 | H12: 22 | J12: 21 | M12: 22 | O12: 10 | S12: 10 | W12: UNKNOWN 2 | AA12: =Y12-Z12 -> 0
A13: Fastest Lap | E13: Pit Lane: | J13: DNF(s): | O13: 11 | S13: 11 | W13: UNKNOWN 3 | AA13: =Y13-Z13 -> 0
A14: Fastest Pitstop | E14: DNS | O14: 12 | W14: Ollie Bearman | AA14: =Y14-Z14 -> 0
A15: # Safety Cars | J15: WDC Points (Race) | O15: 13 | W15: Esteban Ocon | AA15: =Y15-Z15 -> 0
A16: DNF(s) | E16: Race Podium | J16: 25 | O16: 14 | W16: Fernando Alonso | AA16: =Y16-Z16 -> 0
A17: Flop | E17: 2 | F17: 1 | G17: 3 | J17: 18 | O17: 15 | W17: Lance Stroll | AA17: =Y17-Z17 -> 0
A18: Surprise | E18: =L2 | F18: =K2 | G18: =K3 | J18: 15 | O18: 16 | W18: Nico Hulkenberg | AA18: =Y18-Z18 -> 0
E19: Pole | F19: =F2 | J19: 12 | O19: 17 | W19: Gabriel Bortoleto | AA19: =Y19-Z19 -> 0
A20: Weather | E20: Fastest Lap | J20: 10 | O20: 18 | W20: Pierre Gasly | AA20: =Y20-Z20 -> 0
A21: FP1 | E21: Fastest Pitstop | J21: 8 | O21: 19 | W21: Franco Colapinto | AA21: =Y21-Z21 -> 0
A22: Sprint Quali | E22: # Safety Cars | J22: 6 | O22: 20 | W22: Valterri Bottas | AA22: =Y22-Z22 -> 0
A23: Sprint | E23: DNF(s) | F23: =K13 | J23: 4 | O23: 21 | W23: Sergio Perez | AA23: =Y23-Z23 -> 0
A24: Quali | E24: DOTD | J24: 2 | O24: 22
A25: Race | J25: 1
A27: Sprint Predictions | E27: Sprint Starting Grid | J27: Sprint Results
A28: Podium | E28: 1 | H28: 2 | J28: 1 | M28: 2
A29: 2 | B29: 1 | C29: 3 | E29: 3 | H29: 4 | J29: 3 | M29: 4
E30: 5 | H30: 6 | J30: 5 | M30: 6
A31: Pole | E31: 7 | H31: 8 | J31: 7 | M31: 8
A32: Fastest Lap | E32: 9 | H32: 10 | J32: 9 | M32: 10
A33: Fastest Pitstop | E33: 11 | H33: 12 | J33: 11 | M33: 12
A34: # Safety Cars | E34: 13 | H34: 14 | J34: 13 | M34: 14
A35: DNF(s) | E35: 15 | H35: 16 | J35: 15 | M35: 16
A36: Flop | E36: 17 | H36: 18 | J36: 17 | M36: 18
A37: Surprise | E37: 19 | H37: 20 | J37: 19 | M37: 20
E38: 21 | H38: 22 | J38: 21 | M38: 22
A39: FP1 | E39: Pit Lane: | J39: DNF(s):
A40: 2 | B40: 1 | C40: 3 | E40: DNS
A42: FP2 | E42: Sprint Podium | J42: WDC Points (Sprint)
...

Sheet Monaco
A1: Dates | B1: Times (EST) | C1: Session | E1: Race Starting Grid | J1: Race Results | O1: WDC Standings | S1: WCC Standings | W1: Driver | X1: Points Earned | Y1: Qualifying Position | Z1: Race Position | AA1: Positions Gained/Lost
A2: 45813 | B2: 7:30 AM - 8:30 AM | C2: FP1 | E2: 1 | H2: 2 | J2: 1 | M2: 2 | O2: Position | P2: Driver | Q2: Points | S2: Position | T2: Team | U2: Points | W2: Lando Norris | AA2: =Y2-Z2 -> 0
B3: 11:00 AM - 12:00 AM | C3: FP2 | E3: 3 | H3: 4 | J3: 3 | M3: 4 | O3: 1 | S3: 1 | W3: Oscar Piastri | AA3: =Y3-Z3 -> 0
A4: 45814 | B4: 6:30 AM - 7:30 AM | C4: FP3 | E4: 5 | H4: 6 | J4: 5 | M4: 6 | O4: 2 | S4: 2 | W4: George Russell | AA4: =Y4-Z4 -> 0
B5: 10:00 AM - 11:00 AM | C5: Quali | E5: 7 | H5: 8 | J5: 7 | M5: 8 | O5: 3 | S5: 3 | W5: Kimi Antonelli | AA5: =Y5-Z5 -> 0
A6: 45815 | B6: 0.375 | C6: Race | E6: 9 | H6: 10 | J6: 9 | M6: 10 | O6: 4 | S6: 4 | W6: Max Verstappen | AA6: =Y6-Z6 -> 0
E7: 11 | H7: 12 | J7: 11 | M7: 12 | O7: 5 | S7: 5 | W7: UNKNOWN 1 | AA7: =Y7-Z7 -> 0
A8: Race Predictions | E8: 13 | H8: 14 | J8: 13 | M8: 14 | O8: 6 | S8: 6 | W8: Lewis Hamilton | AA8: =Y8-Z8 -> 0
A9: Podium | E9: 15 | H9: 16 | J9: 15 | M9: 16 | O9: 7 | S9: 7 | W9: Charles Leclerc | AA9: =Y9-Z9 -> 0
A10: 2 | B10: 1 | C10: 3 | E10: 17 | H10: 18 | J10: 17 | M10: 18 | O10: 8 | S10: 8 | W10: Carlos Sainz | AA10: =Y10-Z10 -> 0
E11: 19 | H11: 20 | J11: 19 | M11: 20 | O11: 9 | S11: 9 | W11: Alex Albon | AA11: =Y11-Z11 -> 0
A12: Pole | E12: 21 | H12: 22 | J12: 21 | M12: 22 | O12: 10 | S12: 10 | W12: UNKNOWN 2 | AA12: =Y12-Z12 -> 0
A13: Fastest Lap | E13: Pit Lane: | J13: DNF(s): | O13: 11 | S13: 11 | W13: UNKNOWN 3 | AA13: =Y13-Z13 -> 0
A14: Fastest Pitstop | E14: DNS | O14: 12 | W14: Ollie Bearman | AA14: =Y14-Z14 -> 0
A15: # Safety Cars | J15: WDC Points (Race) | O15: 13 | W15: Esteban Ocon | AA15: =Y15-Z15 -> 0
A16: DNF(s) | E16: Race Podium | J16: 25 | O16: 14 | W16: Fernando Alonso | AA16: =Y16-Z16 -> 0
A17: Flop | E17: 2 | F17: 1 | G17: 3 | J17: 18 | O17: 15 | W17: Lance Stroll | AA17: =Y17-Z17 -> 0
A18: Surprise | E18: =L2 | F18: =K2 | G18: =K3 | J18: 15 | O18: 16 | W18: Nico Hulkenberg | AA18: =Y18-Z18 -> 0
E19: Pole | F19: =F2 | J19: 12 | O19: 17 | W19: Gabriel Bortoleto | AA19: =Y19-Z19 -> 0
A20: Weather | E20: Fastest Lap | J20: 10 | O20: 18 | W20: Pierre Gasly | AA20: =Y20-Z20 -> 0
A21: FP1 | E21: Fastest Pitstop | J21: 8 | O21: 19 | W21: Franco Colapinto | AA21: =Y21-Z21 -> 0
A22: FP2 | E22: # Safety Cars | J22: 6 | O22: 20 | W22: Valterri Bottas | AA22: =Y22-Z22 -> 0
A23: FP3 | E23: DNF(s) | F23: =K13 | J23: 4 | O23: 21 | W23: Sergio Perez | AA23: =Y23-Z23 -> 0
A24: Quali | E24: DOTD | J24: 2 | O24: 22
A25: Race | J25: 1
A27: FP1
A28: 2 | B28: 1 | C28: 3
A30: FP2
A31: 2 | B31: 1 | C31: 3
A33: FP3
A34: 2 | B34: 1 | C34: 3

Sheet Barcelona
A1: Dates | B1: Times (EST) | C1: Session | E1: Race Starting Grid | J1: Race Results | O1: WDC Standings | S1: WCC Standings | W1: Driver | X1: Points Earned | Y1: Qualifying Position | Z1: Race Position | AA1: Positions Gained/Lost
A2: 45820 | B2: 7:30 AM - 8:30 AM | C2: FP1 | E2: 1 | H2: 2 | J2: 1 | M2: 2 | O2: Position | P2: Driver | Q2: Points | S2: Position | T2: Team | U2: Points | W2: Lando Norris | AA2: =Y2-Z2 -> 0
B3: 11:00 AM - 12:00 PM | C3: FP2 | E3: 3 | H3: 4 | J3: 3 | M3: 4 | O3: 1 | S3: 1 | W3: Oscar Piastri | AA3: =Y3-Z3 -> 0
A4: 45821 | B4: 6:30 AM - 7:30 AM | C4: FP3 | E4: 5 | H4: 6 | J4: 5 | M4: 6 | O4: 2 | S4: 2 | W4: George Russell | AA4: =Y4-Z4 -> 0
B5: 10:00 AM - 11:00 AM | C5: Quali | E5: 7 | H5: 8 | J5: 7 | M5: 8 | O5: 3 | S5: 3 | W5: Kimi Antonelli | AA5: =Y5-Z5 -> 0
A6: 45822 | B6: 0.375 | C6: Race | E6: 9 | H6: 10 | J6: 9 | M6: 10 | O6: 4 | S6: 4 | W6: Max Verstappen | AA6: =Y6-Z6 -> 0
E7: 11 | H7: 12 | J7: 11 | M7: 12 | O7: 5 | S7: 5 | W7: UNKNOWN 1 | AA7: =Y7-Z7 -> 0
A8: Race Predictions | E8: 13 | H8: 14 | J8: 13 | M8: 14 | O8: 6 | S8: 6 | W8: Lewis Hamilton | AA8: =Y8-Z8 -> 0
A9: Podium | E9: 15 | H9: 16 | J9: 15 | M9: 16 | O9: 7 | S9: 7 | W9: Charles Leclerc | AA9: =Y9-Z9 -> 0
A10: 2 | B10: 1 | C10: 3 | E10: 17 | H10: 18 | J10: 17 | M10: 18 | O10: 8 | S10: 8 | W10: Carlos Sainz | AA10: =Y10-Z10 -> 0
E11: 19 | H11: 20 | J11: 19 | M11: 20 | O11: 9 | S11: 9 | W11: Alex Albon | AA11: =Y11-Z11 -> 0
A12: Pole | E12: 21 | H12: 22 | J12: 21 | M12: 22 | O12: 10 | S12: 10 | W12: UNKNOWN 2 | AA12: =Y12-Z12 -> 0
A13: Fastest Lap | E13: Pit Lane: | J13: DNF(s): | O13: 11 | S13: 11 | W13: UNKNOWN 3 | AA13: =Y13-Z13 -> 0
A14: Fastest Pitstop | E14: DNS | O14: 12 | W14: Ollie Bearman | AA14: =Y14-Z14 -> 0
A15: # Safety Cars | J15: WDC Points (Race) | O15: 13 | W15: Esteban Ocon | AA15: =Y15-Z15 -> 0
A16: DNF(s) | E16: Race Podium | J16: 25 | O16: 14 | W16: Fernando Alonso | AA16: =Y16-Z16 -> 0
A17: Flop | E17: 2 | F17: 1 | G17: 3 | J17: 18 | O17: 15 | W17: Lance Stroll | AA17: =Y17-Z17 -> 0
A18: Surprise | E18: =L2 | F18: =K2 | G18: =K3 | J18: 15 | O18: 16 | W18: Nico Hulkenberg | AA18: =Y18-Z18 -> 0
E19: Pole | F19: =F2 | J19: 12 | O19: 17 | W19: Gabriel Bortoleto | AA19: =Y19-Z19 -> 0
A20: Weather | E20: Fastest Lap | J20: 10 | O20: 18 | W20: Pierre Gasly | AA20: =Y20-Z20 -> 0
A21: FP1 | E21: Fastest Pitstop | J21: 8 | O21: 19 | W21: Franco Colapinto | AA21: =Y21-Z21 -> 0
A22: FP2 | E22: # Safety Cars | J22: 6 | O22: 20 | W22: Valterri Bottas | AA22: =Y22-Z22 -> 0
A23: FP3 | E23: DNF(s) | F23: =K13 | J23: 4 | O23: 21 | W23: Sergio Perez | AA23: =Y23-Z23 -> 0
A24: Quali | E24: DOTD | J24: 2 | O24: 22
A25: Race | J25: 1
A27: FP1
A28: 2 | B28: 1 | C28: 3
A30: FP2
A31: 2 | B31: 1 | C31: 3
A33: FP3
A34: 2 | B34: 1 | C34: 3

Sheet Austria
A1: Dates | B1: Times (EST) | C1: Session | E1: Race Starting Grid | J1: Race Results | O1: WDC Standings | S1: WCC Standings | W1: Driver | X1: Points Earned | Y1: Qualifying Position | Z1: Race Position | AA1: Positions Gained/Lost
A2: 45834 | B2: 7:30 AM - 8:30 AM | C2: FP1 | E2: 1 | H2: 2 | J2: 1 | M2: 2 | O2: Position | P2: Driver | Q2: Points | S2: Position | T2: Team | U2: Points | W2: Lando Norris | AA2: =Y2-Z2 -> 0
B3: 11:00 AM - 12:00 PM | C3: FP2 | E3: 3 | H3: 4 | J3: 3 | M3: 4 | O3: 1 | S3: 1 | W3: Oscar Piastri | AA3: =Y3-Z3 -> 0
A4: 45835 | B4: 6:30 AM - 7:30 AM | C4: FP3 | E4: 5 | H4: 6 | J4: 5 | M4: 6 | O4: 2 | S4: 2 | W4: George Russell | AA4: =Y4-Z4 -> 0
B5: 10:00 AM - 11:00 AM | C5: Quali | E5: 7 | H5: 8 | J5: 7 | M5: 8 | O5: 3 | S5: 3 | W5: Kimi Antonelli | AA5: =Y5-Z5 -> 0
A6: 45836 | B6: 0.375 | C6: Race | E6: 9 | H6: 10 | J6: 9 | M6: 10 | O6: 4 | S6: 4 | W6: Max Verstappen | AA6: =Y6-Z6 -> 0
E7: 11 | H7: 12 | J7: 11 | M7: 12 | O7: 5 | S7: 5 | W7: UNKNOWN 1 | AA7: =Y7-Z7 -> 0
A8: Race Predictions | E8: 13 | H8: 14 | J8: 13 | M8: 14 | O8: 6 | S8: 6 | W8: Lewis Hamilton | AA8: =Y8-Z8 -> 0
A9: Podium | E9: 15 | H9: 16 | J9: 15 | M9: 16 | O9: 7 | S9: 7 | W9: Charles Leclerc | AA9: =Y9-Z9 -> 0
A10: 2 | B10: 1 | C10: 3 | E10: 17 | H10: 18 | J10: 17 | M10: 18 | O10: 8 | S10: 8 | W10: Carlos Sainz | AA10: =Y10-Z10 -> 0
E11: 19 | H11: 20 | J11: 19 | M11: 20 | O11: 9 | S11: 9 | W11: Alex Albon | AA11: =Y11-Z11 -> 0
A12: Pole | E12: 21 | H12: 22 | J12: 21 | M12: 22 | O12: 10 | S12: 10 | W12: UNKNOWN 2 | AA12: =Y12-Z12 -> 0
A13: Fastest Lap | E13: Pit Lane: | J13: DNF(s): | O13: 11 | S13: 11 | W13: UNKNOWN 3 | AA13: =Y13-Z13 -> 0
A14: Fastest Pitstop | E14: DNS | O14: 12 | W14: Ollie Bearman | AA14: =Y14-Z14 -> 0
A15: # Safety Cars | J15: WDC Points (Race) | O15: 13 | W15: Esteban Ocon | AA15: =Y15-Z15 -> 0
A16: DNF(s) | E16: Race Podium | J16: 25 | O16: 14 | W16: Fernando Alonso | AA16: =Y16-Z16 -> 0
A17: Flop | E17: 2 | F17: 1 | G17: 3 | J17: 18 | O17: 15 | W17: Lance Stroll | AA17: =Y17-Z17 -> 0
A18: Surprise | E18: =L2 | F18: =K2 | G18: =K3 | J18: 15 | O18: 16 | W18: Nico Hulkenberg | AA18: =Y18-Z18 -> 0
E19: Pole | F19: =F13 | J19: 12 | O19: 17 | W19: Gabriel Bortoleto | AA19: =Y19-Z19 -> 0
A20: Weather | E20: Fastest Lap | J20: 10 | O20: 18 | W20: Pierre Gasly | AA20: =Y20-Z20 -> 0
A21: FP1 | E21: Fastest Pitstop | J21: 8 | O21: 19 | W21: Franco Colapinto | AA21: =Y21-Z21 -> 0
A22: FP2 | E22: # Safety Cars | J22: 6 | O22: 20 | W22: Valterri Bottas | AA22: =Y22-Z22 -> 0
A23: FP3 | E23: DNF(s) | F23: =K13 | J23: 4 | O23: 21 | W23: Sergio Perez | AA23: =Y23-Z23 -> 0
A24: Quali | E24: DOTD | J24: 2 | O24: 22
A25: Race | J25: 1
A27: FP1
A28: 2 | B28: 1 | C28: 3
A30: FP2
A31: 2 | B31: 1 | C31: 3
A33: FP3
A34: 2 | B34: 1 | C34: 3

Sheet Great Britain
A1: Dates | B1: Times (EST) | C1: Session | E1: Race Starting Grid | J1: Race Results | O1: WDC Standings | S1: WCC Standings | W1: Driver | X1: Points Earned | Y1: Qualifying Position | Z1: Race Position | AA1: Positions Gained/Lost
A2: 45841 | B2: 7:30 AM - 8:30 AM | C2: FP1 | E2: 1 | H2: 2 | J2: 1 | M2: 2 | O2: Position | P2: Driver | Q2: Points | S2: Position | T2: Team | U2: Points | W2: Lando Norris | AA2: =Y2-Z2 -> 0
B3: 11:30 AM - 12:14 PM | C3: Sprint Quali | E3: 3 | H3: 4 | J3: 3 | M3: 4 | O3: 1 | S3: 1 | W3: Oscar Piastri | AA3: =Y3-Z3 -> 0
A4: 45842 | B4: 7:00 AM - 8:00 AM | C4: Sprint | E4: 5 | H4: 6 | J4: 5 | M4: 6 | O4: 2 | S4: 2 | W4: George Russell | AA4: =Y4-Z4 -> 0
B5: 11:00 AM - 12:00 PM | C5: Quali | E5: 7 | H5: 8 | J5: 7 | M5: 8 | O5: 3 | S5: 3 | W5: Kimi Antonelli | AA5: =Y5-Z5 -> 0
A6: 45843 | B6: 0.41666667 | C6: Race | E6: 9 | H6: 10 | J6: 9 | M6: 10 | O6: 4 | S6: 4 | W6: Max Verstappen | AA6: =Y6-Z6 -> 0
E7: 11 | H7: 12 | J7: 11 | M7: 12 | O7: 5 | S7: 5 | W7: UNKNOWN 1 | AA7: =Y7-Z7 -> 0
A8: Race Predictions | E8: 13 | H8: 14 | J8: 13 | M8: 14 | O8: 6 | S8: 6 | W8: Lewis Hamilton | AA8: =Y8-Z8 -> 0
A9: Podium | E9: 15 | H9: 16 | J9: 15 | M9: 16 | O9: 7 | S9: 7 | W9: Charles Leclerc | AA9: =Y9-Z9 -> 0
A10: 2 | B10: 1 | C10: 3 | E10: 17 | H10: 18 | J10: 17 | M10: 18 | O10: 8 | S10: 8 | W10: Carlos Sainz | AA10: =Y10-Z10 -> 0
E11: 19 | H11: 20 | J11: 19 | M11: 20 | O11: 9 | S11: 9 | W11: Alex Albon | AA11: =Y11-Z11 -> 0
A12: Pole | E12: 21 | H12: 22 | J12: 21 | M12: 22 | O12: 10 | S12: 10 | W12: UNKNOWN 2 | AA12: =Y12-Z12 -> 0
A13: Fastest Lap | E13: Pit Lane: | J13: DNF(s): | O13: 11 | S13: 11 | W13: UNKNOWN 3 | AA13: =Y13-Z13 -> 0
A14: Fastest Pitstop | E14: DNS | O14: 12 | W14: Ollie Bearman | AA14: =Y14-Z14 -> 0
A15: # Safety Cars | J15: WDC Points (Race) | O15: 13 | W15: Esteban Ocon | AA15: =Y15-Z15 -> 0
A16: DNF(s) | E16: Race Podium | J16: 25 | O16: 14 | W16: Fernando Alonso | AA16: =Y16-Z16 -> 0
A17: Flop | E17: 2 | F17: 1 | G17: 3 | J17: 18 | O17: 15 | W17: Lance Stroll | AA17: =Y17-Z17 -> 0
A18: Surprise | E18: =L2 | F18: =K2 | G18: =K3 | J18: 15 | O18: 16 | W18: Nico Hulkenberg | AA18: =Y18-Z18 -> 0
E19: Pole | F19: =F2 | J19: 12 | O19: 17 | W19: Gabriel Bortoleto | AA19: =Y19-Z19 -> 0
A20: Weather | E20: Fastest Lap | J20: 10 | O20: 18 | W20: Pierre Gasly | AA20: =Y20-Z20 -> 0
A21: FP1 | E21: Fastest Pitstop | J21: 8 | O21: 19 | W21: Franco Colapinto | AA21: =Y21-Z21 -> 0
A22: Sprint Quali | E22: # Safety Cars | J22: 6 | O22: 20 | W22: Valterri Bottas | AA22: =Y22-Z22 -> 0
A23: Sprint | E23: DNF(s) | F23: =K13 | J23: 4 | O23: 21 | W23: Sergio Perez | AA23: =Y23-Z23 -> 0
A24: Quali | E24: DOTD | J24: 2 | O24: 22
A25: Race | J25: 1
A27: Sprint Predictions | E27: Sprint Starting Grid | J27: Sprint Results
A28: Podium | E28: 1 | H28: 2 | J28: 1 | M28: 2
A29: 2 | B29: 1 | C29: 3 | E29: 3 | H29: 4 | J29: 3 | M29: 4
E30: 5 | H30: 6 | J30: 5 | M30: 6
A31: Pole | E31: 7 | H31: 8 | J31: 7 | M31: 8
A32: Fastest Lap | E32: 9 | H32: 10 | J32: 9 | M32: 10
A33: Fastest Pitstop | E33: 11 | H33: 12 | J33: 11 | M33: 12
A34: # Safety Cars | E34: 13 | H34: 14 | J34: 13 | M34: 14
A35: DNF(s) | E35: 15 | H35: 16 | J35: 15 | M35: 16
A36: Flop | E36: 17 | H36: 18 | J36: 17 | M36: 18
A37: Surprise | E37: 19 | H37: 20 | J37: 19 | M37: 20
E38: 21 | H38: 22 | J38: 21 | M38: 22
A39: FP1 | E39: Pit Lane: | J39: DNF(s):
A40: 2 | B40: 1 | C40: 3 | E40: DNS
A42: FP2 | E42: Sprint Podium | J42: WDC Points (Sprint)
...

Sheet Belgium
A1: Dates | B1: Times (EST) | C1: Session | E1: Race Starting Grid | J1: Race Results | O1: WDC Standings | S1: WCC Standings | W1: Driver | X1: Points Earned | Y1: Qualifying Position | Z1: Race Position | AA1: Positions Gained/Lost
A2: 45855 | B2: 7:30 AM - 8:30 AM | C2: FP1 | E2: 1 | H2: 2 | J2: 1 | M2: 2 | O2: Position | P2: Driver | Q2: Points | S2: Position | T2: Team | U2: Points | W2: Lando Norris | AA2: =Y2-Z2 -> 0
B3: 11:00 AM - 12:00 PM | C3: FP2 | E3: 3 | H3: 4 | J3: 3 | M3: 4 | O3: 1 | S3: 1 | W3: Oscar Piastri | AA3: =Y3-Z3 -> 0
A4: 45856 | B4: 6:30 AM - 7:30 AM | C4: FP3 | E4: 5 | H4: 6 | J4: 5 | M4: 6 | O4: 2 | S4: 2 | W4: George Russell | AA4: =Y4-Z4 -> 0
B5: 10:00 AM - 11:00 AM | C5: Quali | E5: 7 | H5: 8 | J5: 7 | M5: 8 | O5: 3 | S5: 3 | W5: Kimi Antonelli | AA5: =Y5-Z5 -> 0
A6: 45857 | B6: 0.375 | C6: Race | E6: 9 | H6: 10 | J6: 9 | M6: 10 | O6: 4 | S6: 4 | W6: Max Verstappen | AA6: =Y6-Z6 -> 0
E7: 11 | H7: 12 | J7: 11 | M7: 12 | O7: 5 | S7: 5 | W7: UNKNOWN 1 | AA7: =Y7-Z7 -> 0
A8: Race Predictions | E8: 13 | H8: 14 | J8: 13 | M8: 14 | O8: 6 | S8: 6 | W8: Lewis Hamilton | AA8: =Y8-Z8 -> 0
A9: Podium | E9: 15 | H9: 16 | J9: 15 | M9: 16 | O9: 7 | S9: 7 | W9: Charles Leclerc | AA9: =Y9-Z9 -> 0
A10: 2 | B10: 1 | C10: 3 | E10: 17 | H10: 18 | J10: 17 | M10: 18 | O10: 8 | S10: 8 | W10: Carlos Sainz | AA10: =Y10-Z10 -> 0
E11: 19 | H11: 20 | J11: 19 | M11: 20 | O11: 9 | S11: 9 | W11: Alex Albon | AA11: =Y11-Z11 -> 0
A12: Pole | E12: 21 | H12: 22 | J12: 21 | M12: 22 | O12: 10 | S12: 10 | W12: UNKNOWN 2 | AA12: =Y12-Z12 -> 0
A13: Fastest Lap | E13: Pit Lane: | J13: DNF(s): | O13: 11 | S13: 11 | W13: UNKNOWN 3 | AA13: =Y13-Z13 -> 0
A14: Fastest Pitstop | E14: DNS | O14: 12 | W14: Ollie Bearman | AA14: =Y14-Z14 -> 0
A15: # Safety Cars | J15: WDC Points (Race) | O15: 13 | W15: Esteban Ocon | AA15: =Y15-Z15 -> 0
A16: DNF(s) | E16: Race Podium | J16: 25 | O16: 14 | W16: Fernando Alonso | AA16: =Y16-Z16 -> 0
A17: Flop | E17: 2 | F17: 1 | G17: 3 | J17: 18 | O17: 15 | W17: Lance Stroll | AA17: =Y17-Z17 -> 0
A18: Surprise | E18: =L2 | F18: =K2 | G18: =K3 | J18: 15 | O18: 16 | W18: Nico Hulkenberg | AA18: =Y18-Z18 -> 0
E19: Pole | F19: =F2 | J19: 12 | O19: 17 | W19: Gabriel Bortoleto | AA19: =Y19-Z19 -> 0
A20: Weather | E20: Fastest Lap | J20: 10 | O20: 18 | W20: Pierre Gasly | AA20: =Y20-Z20 -> 0
A21: FP1 | E21: Fastest Pitstop | J21: 8 | O21: 19 | W21: Franco Colapinto | AA21: =Y21-Z21 -> 0
A22: FP2 | E22: # Safety Cars | J22: 6 | O22: 20 | W22: Valterri Bottas | AA22: =Y22-Z22 -> 0
A23: FP3 | E23: DNF(s) | F23: =K13 | J23: 4 | O23: 21 | W23: Sergio Perez | AA23: =Y23-Z23 -> 0
A24: Quali | E24: DOTD | J24: 2 | O24: 22
A25: Race | J25: 1
A27: FP1
A28: 2 | B28: 1 | C28: 3
A30: FP2
A31: 2 | B31: 1 | C31: 3
A33: FP3
A34: 2 | B34: 1 | C34: 3

Sheet Hungary
A1: Dates | B1: Times (EST) | C1: Session | E1: Race Starting Grid | J1: Race Results | O1: WDC Standings | S1: WCC Standings | W1: Driver | X1: Points Earned | Y1: Qualifying Position | Z1: Race Position | AA1: Positions Gained/Lost
A2: 45862 | B2: 7:30 AM - 8:30 AM | C2: FP1 | E2: 1 | H2: 2 | J2: 1 | M2: 2 | O2: Position | P2: Driver | Q2: Points | S2: Position | T2: Team | U2: Points | W2: Lando Norris | AA2: =Y2-Z2 -> 0
B3: 11:00 AM - 12:00 PM | C3: FP2 | E3: 3 | H3: 4 | J3: 3 | M3: 4 | O3: 1 | S3: 1 | W3: Oscar Piastri | AA3: =Y3-Z3 -> 0
A4: 45863 | B4: 6:30 AM - 7:30 AM | C4: FP3 | E4: 5 | H4: 6 | J4: 5 | M4: 6 | O4: 2 | S4: 2 | W4: George Russell | AA4: =Y4-Z4 -> 0
B5: 10:00 AM - 11:00 AM | C5: Quali | E5: 7 | H5: 8 | J5: 7 | M5: 8 | O5: 3 | S5: 3 | W5: Kimi Antonelli | AA5: =Y5-Z5 -> 0
A6: 45864 | B6: 0.375 | C6: Race | E6: 9 | H6: 10 | J6: 9 | M6: 10 | O6: 4 | S6: 4 | W6: Max Verstappen | AA6: =Y6-Z6 -> 0
E7: 11 | H7: 12 | J7: 11 | M7: 12 | O7: 5 | S7: 5 | W7: UNKNOWN 1 | AA7: =Y7-Z7 -> 0
A8: Race Predictions | E8: 13 | H8: 14 | J8: 13 | M8: 14 | O8: 6 | S8: 6 | W8: Lewis Hamilton | AA8: =Y8-Z8 -> 0
A9: Podium | E9: 15 | H9: 16 | J9: 15 | M9: 16 | O9: 7 | S9: 7 | W9: Charles Leclerc | AA9: =Y9-Z9 -> 0
A10: 2 | B10: 1 | C10: 3 | E10: 17 | H10: 18 | J10: 17 | M10: 18 | O10: 8 | S10: 8 | W10: Carlos Sainz | AA10: =Y10-Z10 -> 0
E11: 19 | H11: 20 | J11: 19 | M11: 20 | O11: 9 | S11: 9 | W11: Alex Albon | AA11: =Y11-Z11 -> 0
A12: Pole | E12: 21 | H12: 22 | J12: 21 | M12: 22 | O12: 10 | S12: 10 | W12: UNKNOWN 2 | AA12: =Y12-Z12 -> 0
